ERROR:2025-09-04 14:59:14,908:jax._src.xla_bridge:444: Jax plugin configuration error: Exception when calling jax_plugins.xla_cuda12.initialize()
Traceback (most recent call last):
  File "/home/fcastro/.conda/envs/desc-ray/lib/python3.12/site-packages/jax/_src/xla_bridge.py", line 442, in discover_pjrt_plugins
    plugin_module.initialize()
  File "/home/fcastro/.conda/envs/desc-ray/lib/python3.12/site-packages/jax_plugins/xla_cuda12/__init__.py", line 324, in initialize
    _check_cuda_versions(raise_on_first_error=True)
  File "/home/fcastro/.conda/envs/desc-ray/lib/python3.12/site-packages/jax_plugins/xla_cuda12/__init__.py", line 281, in _check_cuda_versions
    local_device_count = cuda_versions.cuda_device_count()
                         ^^^^^^^^^^^^^^^^^^^^^^^^^^^^^^^^^
RuntimeError: jaxlib/cuda/versions_helpers.cc:113: operation cuInit(0) failed: Unknown CUDA error 303; cuGetErrorName failed. This probably means that JAX was unable to load the CUDA libraries.
ERROR:2025-09-04 14:59:14,908:jax._src.xla_bridge:444: Jax plugin configuration error: Exception when calling jax_plugins.xla_cuda12.initialize()
Traceback (most recent call last):
  File "/home/fcastro/.conda/envs/desc-ray/lib/python3.12/site-packages/jax/_src/xla_bridge.py", line 442, in discover_pjrt_plugins
    plugin_module.initialize()
  File "/home/fcastro/.conda/envs/desc-ray/lib/python3.12/site-packages/jax_plugins/xla_cuda12/__init__.py", line 324, in initialize
    _check_cuda_versions(raise_on_first_error=True)
  File "/home/fcastro/.conda/envs/desc-ray/lib/python3.12/site-packages/jax_plugins/xla_cuda12/__init__.py", line 281, in _check_cuda_versions
    local_device_count = cuda_versions.cuda_device_count()
                         ^^^^^^^^^^^^^^^^^^^^^^^^^^^^^^^^^
RuntimeError: jaxlib/cuda/versions_helpers.cc:113: operation cuInit(0) failed: Unknown CUDA error 303; cuGetErrorName failed. This probably means that JAX was unable to load the CUDA libraries.
ERROR:2025-09-04 14:59:14,908:jax._src.xla_bridge:444: Jax plugin configuration error: Exception when calling jax_plugins.xla_cuda12.initialize()
Traceback (most recent call last):
  File "/home/fcastro/.conda/envs/desc-ray/lib/python3.12/site-packages/jax/_src/xla_bridge.py", line 442, in discover_pjrt_plugins
    plugin_module.initialize()
  File "/home/fcastro/.conda/envs/desc-ray/lib/python3.12/site-packages/jax_plugins/xla_cuda12/__init__.py", line 324, in initialize
    _check_cuda_versions(raise_on_first_error=True)
  File "/home/fcastro/.conda/envs/desc-ray/lib/python3.12/site-packages/jax_plugins/xla_cuda12/__init__.py", line 281, in _check_cuda_versions
    local_device_count = cuda_versions.cuda_device_count()
                         ^^^^^^^^^^^^^^^^^^^^^^^^^^^^^^^^^
RuntimeError: jaxlib/cuda/versions_helpers.cc:113: operation cuInit(0) failed: Unknown CUDA error 303; cuGetErrorName failed. This probably means that JAX was unable to load the CUDA libraries.
ERROR:2025-09-04 14:59:14,908:jax._src.xla_bridge:444: Jax plugin configuration error: Exception when calling jax_plugins.xla_cuda12.initialize()
Traceback (most recent call last):
  File "/home/fcastro/.conda/envs/desc-ray/lib/python3.12/site-packages/jax/_src/xla_bridge.py", line 442, in discover_pjrt_plugins
    plugin_module.initialize()
  File "/home/fcastro/.conda/envs/desc-ray/lib/python3.12/site-packages/jax_plugins/xla_cuda12/__init__.py", line 324, in initialize
    _check_cuda_versions(raise_on_first_error=True)
  File "/home/fcastro/.conda/envs/desc-ray/lib/python3.12/site-packages/jax_plugins/xla_cuda12/__init__.py", line 281, in _check_cuda_versions
    local_device_count = cuda_versions.cuda_device_count()
                         ^^^^^^^^^^^^^^^^^^^^^^^^^^^^^^^^^
RuntimeError: jaxlib/cuda/versions_helpers.cc:113: operation cuInit(0) failed: Unknown CUDA error 303; cuGetErrorName failed. This probably means that JAX was unable to load the CUDA libraries.
ERROR:2025-09-04 14:59:14,908:jax._src.xla_bridge:444: Jax plugin configuration error: Exception when calling jax_plugins.xla_cuda12.initialize()
Traceback (most recent call last):
  File "/home/fcastro/.conda/envs/desc-ray/lib/python3.12/site-packages/jax/_src/xla_bridge.py", line 442, in discover_pjrt_plugins
    plugin_module.initialize()
  File "/home/fcastro/.conda/envs/desc-ray/lib/python3.12/site-packages/jax_plugins/xla_cuda12/__init__.py", line 324, in initialize
    _check_cuda_versions(raise_on_first_error=True)
  File "/home/fcastro/.conda/envs/desc-ray/lib/python3.12/site-packages/jax_plugins/xla_cuda12/__init__.py", line 281, in _check_cuda_versions
    local_device_count = cuda_versions.cuda_device_count()
                         ^^^^^^^^^^^^^^^^^^^^^^^^^^^^^^^^^
RuntimeError: jaxlib/cuda/versions_helpers.cc:113: operation cuInit(0) failed: Unknown CUDA error 303; cuGetErrorName failed. This probably means that JAX was unable to load the CUDA libraries.
ERROR:2025-09-04 14:59:14,908:jax._src.xla_bridge:444: Jax plugin configuration error: Exception when calling jax_plugins.xla_cuda12.initialize()
Traceback (most recent call last):
  File "/home/fcastro/.conda/envs/desc-ray/lib/python3.12/site-packages/jax/_src/xla_bridge.py", line 442, in discover_pjrt_plugins
    plugin_module.initialize()
  File "/home/fcastro/.conda/envs/desc-ray/lib/python3.12/site-packages/jax_plugins/xla_cuda12/__init__.py", line 324, in initialize
    _check_cuda_versions(raise_on_first_error=True)
  File "/home/fcastro/.conda/envs/desc-ray/lib/python3.12/site-packages/jax_plugins/xla_cuda12/__init__.py", line 281, in _check_cuda_versions
    local_device_count = cuda_versions.cuda_device_count()
                         ^^^^^^^^^^^^^^^^^^^^^^^^^^^^^^^^^
RuntimeError: jaxlib/cuda/versions_helpers.cc:113: operation cuInit(0) failed: Unknown CUDA error 303; cuGetErrorName failed. This probably means that JAX was unable to load the CUDA libraries.
ERROR:2025-09-04 14:59:14,908:jax._src.xla_bridge:444: Jax plugin configuration error: Exception when calling jax_plugins.xla_cuda12.initialize()
Traceback (most recent call last):
  File "/home/fcastro/.conda/envs/desc-ray/lib/python3.12/site-packages/jax/_src/xla_bridge.py", line 442, in discover_pjrt_plugins
    plugin_module.initialize()
  File "/home/fcastro/.conda/envs/desc-ray/lib/python3.12/site-packages/jax_plugins/xla_cuda12/__init__.py", line 324, in initialize
    _check_cuda_versions(raise_on_first_error=True)
  File "/home/fcastro/.conda/envs/desc-ray/lib/python3.12/site-packages/jax_plugins/xla_cuda12/__init__.py", line 281, in _check_cuda_versions
    local_device_count = cuda_versions.cuda_device_count()
                         ^^^^^^^^^^^^^^^^^^^^^^^^^^^^^^^^^
RuntimeError: jaxlib/cuda/versions_helpers.cc:113: operation cuInit(0) failed: Unknown CUDA error 303; cuGetErrorName failed. This probably means that JAX was unable to load the CUDA libraries.
ERROR:2025-09-04 14:59:14,908:jax._src.xla_bridge:444: Jax plugin configuration error: Exception when calling jax_plugins.xla_cuda12.initialize()
Traceback (most recent call last):
  File "/home/fcastro/.conda/envs/desc-ray/lib/python3.12/site-packages/jax/_src/xla_bridge.py", line 442, in discover_pjrt_plugins
    plugin_module.initialize()
  File "/home/fcastro/.conda/envs/desc-ray/lib/python3.12/site-packages/jax_plugins/xla_cuda12/__init__.py", line 324, in initialize
    _check_cuda_versions(raise_on_first_error=True)
  File "/home/fcastro/.conda/envs/desc-ray/lib/python3.12/site-packages/jax_plugins/xla_cuda12/__init__.py", line 281, in _check_cuda_versions
    local_device_count = cuda_versions.cuda_device_count()
                         ^^^^^^^^^^^^^^^^^^^^^^^^^^^^^^^^^
RuntimeError: jaxlib/cuda/versions_helpers.cc:113: operation cuInit(0) failed: Unknown CUDA error 303; cuGetErrorName failed. This probably means that JAX was unable to load the CUDA libraries.
ERROR:2025-09-04 14:59:14,908:jax._src.xla_bridge:444: Jax plugin configuration error: Exception when calling jax_plugins.xla_cuda12.initialize()
Traceback (most recent call last):
  File "/home/fcastro/.conda/envs/desc-ray/lib/python3.12/site-packages/jax/_src/xla_bridge.py", line 442, in discover_pjrt_plugins
    plugin_module.initialize()
  File "/home/fcastro/.conda/envs/desc-ray/lib/python3.12/site-packages/jax_plugins/xla_cuda12/__init__.py", line 324, in initialize
    _check_cuda_versions(raise_on_first_error=True)
  File "/home/fcastro/.conda/envs/desc-ray/lib/python3.12/site-packages/jax_plugins/xla_cuda12/__init__.py", line 281, in _check_cuda_versions
    local_device_count = cuda_versions.cuda_device_count()
                         ^^^^^^^^^^^^^^^^^^^^^^^^^^^^^^^^^
RuntimeError: jaxlib/cuda/versions_helpers.cc:113: operation cuInit(0) failed: Unknown CUDA error 303; cuGetErrorName failed. This probably means that JAX was unable to load the CUDA libraries.
ERROR:2025-09-04 14:59:15,027:jax._src.xla_bridge:444: Jax plugin configuration error: Exception when calling jax_plugins.xla_cuda12.initialize()
Traceback (most recent call last):
  File "/home/fcastro/.conda/envs/desc-ray/lib/python3.12/site-packages/jax/_src/xla_bridge.py", line 442, in discover_pjrt_plugins
    plugin_module.initialize()
  File "/home/fcastro/.conda/envs/desc-ray/lib/python3.12/site-packages/jax_plugins/xla_cuda12/__init__.py", line 324, in initialize
    _check_cuda_versions(raise_on_first_error=True)
  File "/home/fcastro/.conda/envs/desc-ray/lib/python3.12/site-packages/jax_plugins/xla_cuda12/__init__.py", line 281, in _check_cuda_versions
    local_device_count = cuda_versions.cuda_device_count()
                         ^^^^^^^^^^^^^^^^^^^^^^^^^^^^^^^^^
RuntimeError: jaxlib/cuda/versions_helpers.cc:113: operation cuInit(0) failed: Unknown CUDA error 303; cuGetErrorName failed. This probably means that JAX was unable to load the CUDA libraries.
ERROR:2025-09-04 14:59:15,027:jax._src.xla_bridge:444: Jax plugin configuration error: Exception when calling jax_plugins.xla_cuda12.initialize()
Traceback (most recent call last):
  File "/home/fcastro/.conda/envs/desc-ray/lib/python3.12/site-packages/jax/_src/xla_bridge.py", line 442, in discover_pjrt_plugins
    plugin_module.initialize()
  File "/home/fcastro/.conda/envs/desc-ray/lib/python3.12/site-packages/jax_plugins/xla_cuda12/__init__.py", line 324, in initialize
    _check_cuda_versions(raise_on_first_error=True)
  File "/home/fcastro/.conda/envs/desc-ray/lib/python3.12/site-packages/jax_plugins/xla_cuda12/__init__.py", line 281, in _check_cuda_versions
    local_device_count = cuda_versions.cuda_device_count()
                         ^^^^^^^^^^^^^^^^^^^^^^^^^^^^^^^^^
RuntimeError: jaxlib/cuda/versions_helpers.cc:113: operation cuInit(0) failed: Unknown CUDA error 303; cuGetErrorName failed. This probably means that JAX was unable to load the CUDA libraries.
ERROR:2025-09-04 14:59:15,027:jax._src.xla_bridge:444: Jax plugin configuration error: Exception when calling jax_plugins.xla_cuda12.initialize()
Traceback (most recent call last):
  File "/home/fcastro/.conda/envs/desc-ray/lib/python3.12/site-packages/jax/_src/xla_bridge.py", line 442, in discover_pjrt_plugins
    plugin_module.initialize()
  File "/home/fcastro/.conda/envs/desc-ray/lib/python3.12/site-packages/jax_plugins/xla_cuda12/__init__.py", line 324, in initialize
    _check_cuda_versions(raise_on_first_error=True)
  File "/home/fcastro/.conda/envs/desc-ray/lib/python3.12/site-packages/jax_plugins/xla_cuda12/__init__.py", line 281, in _check_cuda_versions
    local_device_count = cuda_versions.cuda_device_count()
                         ^^^^^^^^^^^^^^^^^^^^^^^^^^^^^^^^^
RuntimeError: jaxlib/cuda/versions_helpers.cc:113: operation cuInit(0) failed: Unknown CUDA error 303; cuGetErrorName failed. This probably means that JAX was unable to load the CUDA libraries.
ERROR:2025-09-04 14:59:15,027:jax._src.xla_bridge:444: Jax plugin configuration error: Exception when calling jax_plugins.xla_cuda12.initialize()
Traceback (most recent call last):
  File "/home/fcastro/.conda/envs/desc-ray/lib/python3.12/site-packages/jax/_src/xla_bridge.py", line 442, in discover_pjrt_plugins
    plugin_module.initialize()
  File "/home/fcastro/.conda/envs/desc-ray/lib/python3.12/site-packages/jax_plugins/xla_cuda12/__init__.py", line 324, in initialize
    _check_cuda_versions(raise_on_first_error=True)
  File "/home/fcastro/.conda/envs/desc-ray/lib/python3.12/site-packages/jax_plugins/xla_cuda12/__init__.py", line 281, in _check_cuda_versions
    local_device_count = cuda_versions.cuda_device_count()
                         ^^^^^^^^^^^^^^^^^^^^^^^^^^^^^^^^^
RuntimeError: jaxlib/cuda/versions_helpers.cc:113: operation cuInit(0) failed: Unknown CUDA error 303; cuGetErrorName failed. This probably means that JAX was unable to load the CUDA libraries.
ERROR:2025-09-04 14:59:15,027:jax._src.xla_bridge:444: Jax plugin configuration error: Exception when calling jax_plugins.xla_cuda12.initialize()
Traceback (most recent call last):
  File "/home/fcastro/.conda/envs/desc-ray/lib/python3.12/site-packages/jax/_src/xla_bridge.py", line 442, in discover_pjrt_plugins
    plugin_module.initialize()
  File "/home/fcastro/.conda/envs/desc-ray/lib/python3.12/site-packages/jax_plugins/xla_cuda12/__init__.py", line 324, in initialize
    _check_cuda_versions(raise_on_first_error=True)
  File "/home/fcastro/.conda/envs/desc-ray/lib/python3.12/site-packages/jax_plugins/xla_cuda12/__init__.py", line 281, in _check_cuda_versions
    local_device_count = cuda_versions.cuda_device_count()
                         ^^^^^^^^^^^^^^^^^^^^^^^^^^^^^^^^^
RuntimeError: jaxlib/cuda/versions_helpers.cc:113: operation cuInit(0) failed: Unknown CUDA error 303; cuGetErrorName failed. This probably means that JAX was unable to load the CUDA libraries.
ERROR:2025-09-04 14:59:15,027:jax._src.xla_bridge:444: Jax plugin configuration error: Exception when calling jax_plugins.xla_cuda12.initialize()
Traceback (most recent call last):
  File "/home/fcastro/.conda/envs/desc-ray/lib/python3.12/site-packages/jax/_src/xla_bridge.py", line 442, in discover_pjrt_plugins
    plugin_module.initialize()
  File "/home/fcastro/.conda/envs/desc-ray/lib/python3.12/site-packages/jax_plugins/xla_cuda12/__init__.py", line 324, in initialize
    _check_cuda_versions(raise_on_first_error=True)
  File "/home/fcastro/.conda/envs/desc-ray/lib/python3.12/site-packages/jax_plugins/xla_cuda12/__init__.py", line 281, in _check_cuda_versions
    local_device_count = cuda_versions.cuda_device_count()
                         ^^^^^^^^^^^^^^^^^^^^^^^^^^^^^^^^^
RuntimeError: jaxlib/cuda/versions_helpers.cc:113: operation cuInit(0) failed: Unknown CUDA error 303; cuGetErrorName failed. This probably means that JAX was unable to load the CUDA libraries.
ERROR:2025-09-04 14:59:15,027:jax._src.xla_bridge:444: Jax plugin configuration error: Exception when calling jax_plugins.xla_cuda12.initialize()
Traceback (most recent call last):
  File "/home/fcastro/.conda/envs/desc-ray/lib/python3.12/site-packages/jax/_src/xla_bridge.py", line 442, in discover_pjrt_plugins
    plugin_module.initialize()
  File "/home/fcastro/.conda/envs/desc-ray/lib/python3.12/site-packages/jax_plugins/xla_cuda12/__init__.py", line 324, in initialize
    _check_cuda_versions(raise_on_first_error=True)
  File "/home/fcastro/.conda/envs/desc-ray/lib/python3.12/site-packages/jax_plugins/xla_cuda12/__init__.py", line 281, in _check_cuda_versions
    local_device_count = cuda_versions.cuda_device_count()
                         ^^^^^^^^^^^^^^^^^^^^^^^^^^^^^^^^^
RuntimeError: jaxlib/cuda/versions_helpers.cc:113: operation cuInit(0) failed: Unknown CUDA error 303; cuGetErrorName failed. This probably means that JAX was unable to load the CUDA libraries.
ERROR:2025-09-04 14:59:15,027:jax._src.xla_bridge:444: Jax plugin configuration error: Exception when calling jax_plugins.xla_cuda12.initialize()
Traceback (most recent call last):
  File "/home/fcastro/.conda/envs/desc-ray/lib/python3.12/site-packages/jax/_src/xla_bridge.py", line 442, in discover_pjrt_plugins
    plugin_module.initialize()
  File "/home/fcastro/.conda/envs/desc-ray/lib/python3.12/site-packages/jax_plugins/xla_cuda12/__init__.py", line 324, in initialize
    _check_cuda_versions(raise_on_first_error=True)
  File "/home/fcastro/.conda/envs/desc-ray/lib/python3.12/site-packages/jax_plugins/xla_cuda12/__init__.py", line 281, in _check_cuda_versions
    local_device_count = cuda_versions.cuda_device_count()
                         ^^^^^^^^^^^^^^^^^^^^^^^^^^^^^^^^^
RuntimeError: jaxlib/cuda/versions_helpers.cc:113: operation cuInit(0) failed: Unknown CUDA error 303; cuGetErrorName failed. This probably means that JAX was unable to load the CUDA libraries.
ERROR:2025-09-04 14:59:15,027:jax._src.xla_bridge:444: Jax plugin configuration error: Exception when calling jax_plugins.xla_cuda12.initialize()
Traceback (most recent call last):
  File "/home/fcastro/.conda/envs/desc-ray/lib/python3.12/site-packages/jax/_src/xla_bridge.py", line 442, in discover_pjrt_plugins
    plugin_module.initialize()
  File "/home/fcastro/.conda/envs/desc-ray/lib/python3.12/site-packages/jax_plugins/xla_cuda12/__init__.py", line 324, in initialize
    _check_cuda_versions(raise_on_first_error=True)
  File "/home/fcastro/.conda/envs/desc-ray/lib/python3.12/site-packages/jax_plugins/xla_cuda12/__init__.py", line 281, in _check_cuda_versions
    local_device_count = cuda_versions.cuda_device_count()
                         ^^^^^^^^^^^^^^^^^^^^^^^^^^^^^^^^^
RuntimeError: jaxlib/cuda/versions_helpers.cc:113: operation cuInit(0) failed: Unknown CUDA error 303; cuGetErrorName failed. This probably means that JAX was unable to load the CUDA libraries.
Traceback (most recent call last):
  File "/home/fcastro/DESC/docs/notebooks/tutorials/sources/both/RQA/test/mpi6.py", line 211, in <module>
    from mpi4py import MPI
ModuleNotFoundError: No module named 'mpi4py'
Traceback (most recent call last):
  File "/home/fcastro/DESC/docs/notebooks/tutorials/sources/both/RQA/test/mpi6.py", line 211, in <module>
    from mpi4py import MPI
ModuleNotFoundError: No module named 'mpi4py'
Traceback (most recent call last):
  File "/home/fcastro/DESC/docs/notebooks/tutorials/sources/both/RQA/test/mpi6.py", line 211, in <module>
Traceback (most recent call last):
  File "/home/fcastro/DESC/docs/notebooks/tutorials/sources/both/RQA/test/mpi6.py", line 211, in <module>
    from mpi4py import MPI
    from mpi4py import MPI
ModuleNotFoundError: No module named 'mpi4py'
ModuleNotFoundError: No module named 'mpi4py'
Traceback (most recent call last):
  File "/home/fcastro/DESC/docs/notebooks/tutorials/sources/both/RQA/test/mpi6.py", line 211, in <module>
Traceback (most recent call last):
  File "/home/fcastro/DESC/docs/notebooks/tutorials/sources/both/RQA/test/mpi6.py", line 211, in <module>
    from mpi4py import MPI
    from mpi4py import MPI
ModuleNotFoundError: No module named 'mpi4py'
ModuleNotFoundError: No module named 'mpi4py'
Traceback (most recent call last):
  File "/home/fcastro/DESC/docs/notebooks/tutorials/sources/both/RQA/test/mpi6.py", line 211, in <module>
    from mpi4py import MPI
ModuleNotFoundError: No module named 'mpi4py'
Traceback (most recent call last):
  File "/home/fcastro/DESC/docs/notebooks/tutorials/sources/both/RQA/test/mpi6.py", line 211, in <module>
    from mpi4py import MPI
ModuleNotFoundError: No module named 'mpi4py'
Traceback (most recent call last):
  File "/home/fcastro/DESC/docs/notebooks/tutorials/sources/both/RQA/test/mpi6.py", line 211, in <module>
Traceback (most recent call last):
  File "/home/fcastro/DESC/docs/notebooks/tutorials/sources/both/RQA/test/mpi6.py", line 211, in <module>
    from mpi4py import MPI
    from mpi4py import MPI
ModuleNotFoundError: No module named 'mpi4py'
Traceback (most recent call last):
Traceback (most recent call last):
ModuleNotFoundError: No module named 'mpi4py'
  File "/home/fcastro/DESC/docs/notebooks/tutorials/sources/both/RQA/test/mpi6.py", line 211, in <module>
  File "/home/fcastro/DESC/docs/notebooks/tutorials/sources/both/RQA/test/mpi6.py", line 211, in <module>
    from mpi4py import MPI
ModuleNotFoundError: No module named 'mpi4py'
    from mpi4py import MPI
ModuleNotFoundError: No module named 'mpi4py'
Traceback (most recent call last):
  File "/home/fcastro/DESC/docs/notebooks/tutorials/sources/both/RQA/test/mpi6.py", line 211, in <module>
    from mpi4py import MPI
ModuleNotFoundError: No module named 'mpi4py'
Traceback (most recent call last):
  File "/home/fcastro/DESC/docs/notebooks/tutorials/sources/both/RQA/test/mpi6.py", line 211, in <module>
    from mpi4py import MPI
ModuleNotFoundError: No module named 'mpi4py'
srun: error: stellar-i07n19: task 17: Exited with exit code 1
srun: Terminating StepId=2176232.0
slurmstepd: error: *** STEP 2176232.0 ON stellar-i07n7 CANCELLED AT 2025-09-04T14:59:35 ***
srun: error: stellar-i07n7: tasks 0-8: Terminated
srun: error: stellar-i07n19: tasks 9-16: Terminated
srun: Force Terminated StepId=2176232.0
