[NbConvertApp] Converting notebook mpi5.ipynb to notebook
[NbConvertApp] Writing 177467 bytes to mpi5_executed.ipynb
[NbConvertApp] Converting notebook mpi5_executed.ipynb to script
[NbConvertApp] Writing 9814 bytes to mpi5_executed.py
ERROR:2025-09-03 21:34:49,111:jax._src.xla_bridge:444: Jax plugin configuration error: Exception when calling jax_plugins.xla_cuda12.initialize()
Traceback (most recent call last):
  File "/home/fcastro/.conda/envs/desc-ray/lib/python3.12/site-packages/jax/_src/xla_bridge.py", line 442, in discover_pjrt_plugins
    plugin_module.initialize()
  File "/home/fcastro/.conda/envs/desc-ray/lib/python3.12/site-packages/jax_plugins/xla_cuda12/__init__.py", line 324, in initialize
    _check_cuda_versions(raise_on_first_error=True)
  File "/home/fcastro/.conda/envs/desc-ray/lib/python3.12/site-packages/jax_plugins/xla_cuda12/__init__.py", line 281, in _check_cuda_versions
    local_device_count = cuda_versions.cuda_device_count()
                         ^^^^^^^^^^^^^^^^^^^^^^^^^^^^^^^^^
RuntimeError: jaxlib/cuda/versions_helpers.cc:113: operation cuInit(0) failed: Unknown CUDA error 303; cuGetErrorName failed. This probably means that JAX was unable to load the CUDA libraries.
ERROR:2025-09-03 21:34:49,111:jax._src.xla_bridge:444: Jax plugin configuration error: Exception when calling jax_plugins.xla_cuda12.initialize()
Traceback (most recent call last):
  File "/home/fcastro/.conda/envs/desc-ray/lib/python3.12/site-packages/jax/_src/xla_bridge.py", line 442, in discover_pjrt_plugins
    plugin_module.initialize()
  File "/home/fcastro/.conda/envs/desc-ray/lib/python3.12/site-packages/jax_plugins/xla_cuda12/__init__.py", line 324, in initialize
    _check_cuda_versions(raise_on_first_error=True)
  File "/home/fcastro/.conda/envs/desc-ray/lib/python3.12/site-packages/jax_plugins/xla_cuda12/__init__.py", line 281, in _check_cuda_versions
    local_device_count = cuda_versions.cuda_device_count()
                         ^^^^^^^^^^^^^^^^^^^^^^^^^^^^^^^^^
RuntimeError: jaxlib/cuda/versions_helpers.cc:113: operation cuInit(0) failed: Unknown CUDA error 303; cuGetErrorName failed. This probably means that JAX was unable to load the CUDA libraries.
ERROR:2025-09-03 21:34:49,111:jax._src.xla_bridge:444: Jax plugin configuration error: Exception when calling jax_plugins.xla_cuda12.initialize()
Traceback (most recent call last):
  File "/home/fcastro/.conda/envs/desc-ray/lib/python3.12/site-packages/jax/_src/xla_bridge.py", line 442, in discover_pjrt_plugins
    plugin_module.initialize()
  File "/home/fcastro/.conda/envs/desc-ray/lib/python3.12/site-packages/jax_plugins/xla_cuda12/__init__.py", line 324, in initialize
    _check_cuda_versions(raise_on_first_error=True)
  File "/home/fcastro/.conda/envs/desc-ray/lib/python3.12/site-packages/jax_plugins/xla_cuda12/__init__.py", line 281, in _check_cuda_versions
    local_device_count = cuda_versions.cuda_device_count()
                         ^^^^^^^^^^^^^^^^^^^^^^^^^^^^^^^^^
RuntimeError: jaxlib/cuda/versions_helpers.cc:113: operation cuInit(0) failed: Unknown CUDA error 303; cuGetErrorName failed. This probably means that JAX was unable to load the CUDA libraries.
ERROR:2025-09-03 21:34:49,111:jax._src.xla_bridge:444: Jax plugin configuration error: Exception when calling jax_plugins.xla_cuda12.initialize()
Traceback (most recent call last):
  File "/home/fcastro/.conda/envs/desc-ray/lib/python3.12/site-packages/jax/_src/xla_bridge.py", line 442, in discover_pjrt_plugins
    plugin_module.initialize()
  File "/home/fcastro/.conda/envs/desc-ray/lib/python3.12/site-packages/jax_plugins/xla_cuda12/__init__.py", line 324, in initialize
    _check_cuda_versions(raise_on_first_error=True)
  File "/home/fcastro/.conda/envs/desc-ray/lib/python3.12/site-packages/jax_plugins/xla_cuda12/__init__.py", line 281, in _check_cuda_versions
    local_device_count = cuda_versions.cuda_device_count()
                         ^^^^^^^^^^^^^^^^^^^^^^^^^^^^^^^^^
RuntimeError: jaxlib/cuda/versions_helpers.cc:113: operation cuInit(0) failed: Unknown CUDA error 303; cuGetErrorName failed. This probably means that JAX was unable to load the CUDA libraries.
ERROR:2025-09-03 21:34:49,111:jax._src.xla_bridge:444: Jax plugin configuration error: Exception when calling jax_plugins.xla_cuda12.initialize()
Traceback (most recent call last):
  File "/home/fcastro/.conda/envs/desc-ray/lib/python3.12/site-packages/jax/_src/xla_bridge.py", line 442, in discover_pjrt_plugins
    plugin_module.initialize()
  File "/home/fcastro/.conda/envs/desc-ray/lib/python3.12/site-packages/jax_plugins/xla_cuda12/__init__.py", line 324, in initialize
    _check_cuda_versions(raise_on_first_error=True)
  File "/home/fcastro/.conda/envs/desc-ray/lib/python3.12/site-packages/jax_plugins/xla_cuda12/__init__.py", line 281, in _check_cuda_versions
    local_device_count = cuda_versions.cuda_device_count()
                         ^^^^^^^^^^^^^^^^^^^^^^^^^^^^^^^^^
RuntimeError: jaxlib/cuda/versions_helpers.cc:113: operation cuInit(0) failed: Unknown CUDA error 303; cuGetErrorName failed. This probably means that JAX was unable to load the CUDA libraries.
ERROR:2025-09-03 21:34:49,111:jax._src.xla_bridge:444: Jax plugin configuration error: Exception when calling jax_plugins.xla_cuda12.initialize()
Traceback (most recent call last):
  File "/home/fcastro/.conda/envs/desc-ray/lib/python3.12/site-packages/jax/_src/xla_bridge.py", line 442, in discover_pjrt_plugins
    plugin_module.initialize()
  File "/home/fcastro/.conda/envs/desc-ray/lib/python3.12/site-packages/jax_plugins/xla_cuda12/__init__.py", line 324, in initialize
    _check_cuda_versions(raise_on_first_error=True)
  File "/home/fcastro/.conda/envs/desc-ray/lib/python3.12/site-packages/jax_plugins/xla_cuda12/__init__.py", line 281, in _check_cuda_versions
    local_device_count = cuda_versions.cuda_device_count()
                         ^^^^^^^^^^^^^^^^^^^^^^^^^^^^^^^^^
RuntimeError: jaxlib/cuda/versions_helpers.cc:113: operation cuInit(0) failed: Unknown CUDA error 303; cuGetErrorName failed. This probably means that JAX was unable to load the CUDA libraries.
ERROR:2025-09-03 21:34:49,112:jax._src.xla_bridge:444: Jax plugin configuration error: Exception when calling jax_plugins.xla_cuda12.initialize()
Traceback (most recent call last):
  File "/home/fcastro/.conda/envs/desc-ray/lib/python3.12/site-packages/jax/_src/xla_bridge.py", line 442, in discover_pjrt_plugins
    plugin_module.initialize()
  File "/home/fcastro/.conda/envs/desc-ray/lib/python3.12/site-packages/jax_plugins/xla_cuda12/__init__.py", line 324, in initialize
    _check_cuda_versions(raise_on_first_error=True)
  File "/home/fcastro/.conda/envs/desc-ray/lib/python3.12/site-packages/jax_plugins/xla_cuda12/__init__.py", line 281, in _check_cuda_versions
    local_device_count = cuda_versions.cuda_device_count()
                         ^^^^^^^^^^^^^^^^^^^^^^^^^^^^^^^^^
RuntimeError: jaxlib/cuda/versions_helpers.cc:113: operation cuInit(0) failed: Unknown CUDA error 303; cuGetErrorName failed. This probably means that JAX was unable to load the CUDA libraries.
ERROR:2025-09-03 21:34:49,112:jax._src.xla_bridge:444: Jax plugin configuration error: Exception when calling jax_plugins.xla_cuda12.initialize()
Traceback (most recent call last):
  File "/home/fcastro/.conda/envs/desc-ray/lib/python3.12/site-packages/jax/_src/xla_bridge.py", line 442, in discover_pjrt_plugins
    plugin_module.initialize()
  File "/home/fcastro/.conda/envs/desc-ray/lib/python3.12/site-packages/jax_plugins/xla_cuda12/__init__.py", line 324, in initialize
    _check_cuda_versions(raise_on_first_error=True)
  File "/home/fcastro/.conda/envs/desc-ray/lib/python3.12/site-packages/jax_plugins/xla_cuda12/__init__.py", line 281, in _check_cuda_versions
    local_device_count = cuda_versions.cuda_device_count()
                         ^^^^^^^^^^^^^^^^^^^^^^^^^^^^^^^^^
RuntimeError: jaxlib/cuda/versions_helpers.cc:113: operation cuInit(0) failed: Unknown CUDA error 303; cuGetErrorName failed. This probably means that JAX was unable to load the CUDA libraries.
ERROR:2025-09-03 21:34:49,112:jax._src.xla_bridge:444: Jax plugin configuration error: Exception when calling jax_plugins.xla_cuda12.initialize()
Traceback (most recent call last):
  File "/home/fcastro/.conda/envs/desc-ray/lib/python3.12/site-packages/jax/_src/xla_bridge.py", line 442, in discover_pjrt_plugins
    plugin_module.initialize()
  File "/home/fcastro/.conda/envs/desc-ray/lib/python3.12/site-packages/jax_plugins/xla_cuda12/__init__.py", line 324, in initialize
    _check_cuda_versions(raise_on_first_error=True)
  File "/home/fcastro/.conda/envs/desc-ray/lib/python3.12/site-packages/jax_plugins/xla_cuda12/__init__.py", line 281, in _check_cuda_versions
    local_device_count = cuda_versions.cuda_device_count()
                         ^^^^^^^^^^^^^^^^^^^^^^^^^^^^^^^^^
RuntimeError: jaxlib/cuda/versions_helpers.cc:113: operation cuInit(0) failed: Unknown CUDA error 303; cuGetErrorName failed. This probably means that JAX was unable to load the CUDA libraries.
ERROR:2025-09-03 21:34:49,422:jax._src.xla_bridge:444: Jax plugin configuration error: Exception when calling jax_plugins.xla_cuda12.initialize()
Traceback (most recent call last):
  File "/home/fcastro/.conda/envs/desc-ray/lib/python3.12/site-packages/jax/_src/xla_bridge.py", line 442, in discover_pjrt_plugins
    plugin_module.initialize()
  File "/home/fcastro/.conda/envs/desc-ray/lib/python3.12/site-packages/jax_plugins/xla_cuda12/__init__.py", line 324, in initialize
    _check_cuda_versions(raise_on_first_error=True)
  File "/home/fcastro/.conda/envs/desc-ray/lib/python3.12/site-packages/jax_plugins/xla_cuda12/__init__.py", line 281, in _check_cuda_versions
    local_device_count = cuda_versions.cuda_device_count()
                         ^^^^^^^^^^^^^^^^^^^^^^^^^^^^^^^^^
RuntimeError: jaxlib/cuda/versions_helpers.cc:113: operation cuInit(0) failed: Unknown CUDA error 303; cuGetErrorName failed. This probably means that JAX was unable to load the CUDA libraries.
ERROR:2025-09-03 21:34:49,422:jax._src.xla_bridge:444: Jax plugin configuration error: Exception when calling jax_plugins.xla_cuda12.initialize()
Traceback (most recent call last):
  File "/home/fcastro/.conda/envs/desc-ray/lib/python3.12/site-packages/jax/_src/xla_bridge.py", line 442, in discover_pjrt_plugins
    plugin_module.initialize()
  File "/home/fcastro/.conda/envs/desc-ray/lib/python3.12/site-packages/jax_plugins/xla_cuda12/__init__.py", line 324, in initialize
    _check_cuda_versions(raise_on_first_error=True)
  File "/home/fcastro/.conda/envs/desc-ray/lib/python3.12/site-packages/jax_plugins/xla_cuda12/__init__.py", line 281, in _check_cuda_versions
    local_device_count = cuda_versions.cuda_device_count()
                         ^^^^^^^^^^^^^^^^^^^^^^^^^^^^^^^^^
RuntimeError: jaxlib/cuda/versions_helpers.cc:113: operation cuInit(0) failed: Unknown CUDA error 303; cuGetErrorName failed. This probably means that JAX was unable to load the CUDA libraries.
ERROR:2025-09-03 21:34:49,422:jax._src.xla_bridge:444: Jax plugin configuration error: Exception when calling jax_plugins.xla_cuda12.initialize()
Traceback (most recent call last):
  File "/home/fcastro/.conda/envs/desc-ray/lib/python3.12/site-packages/jax/_src/xla_bridge.py", line 442, in discover_pjrt_plugins
    plugin_module.initialize()
  File "/home/fcastro/.conda/envs/desc-ray/lib/python3.12/site-packages/jax_plugins/xla_cuda12/__init__.py", line 324, in initialize
    _check_cuda_versions(raise_on_first_error=True)
  File "/home/fcastro/.conda/envs/desc-ray/lib/python3.12/site-packages/jax_plugins/xla_cuda12/__init__.py", line 281, in _check_cuda_versions
    local_device_count = cuda_versions.cuda_device_count()
                         ^^^^^^^^^^^^^^^^^^^^^^^^^^^^^^^^^
RuntimeError: jaxlib/cuda/versions_helpers.cc:113: operation cuInit(0) failed: Unknown CUDA error 303; cuGetErrorName failed. This probably means that JAX was unable to load the CUDA libraries.
ERROR:2025-09-03 21:34:49,422:jax._src.xla_bridge:444: Jax plugin configuration error: Exception when calling jax_plugins.xla_cuda12.initialize()
Traceback (most recent call last):
  File "/home/fcastro/.conda/envs/desc-ray/lib/python3.12/site-packages/jax/_src/xla_bridge.py", line 442, in discover_pjrt_plugins
    plugin_module.initialize()
  File "/home/fcastro/.conda/envs/desc-ray/lib/python3.12/site-packages/jax_plugins/xla_cuda12/__init__.py", line 324, in initialize
    _check_cuda_versions(raise_on_first_error=True)
  File "/home/fcastro/.conda/envs/desc-ray/lib/python3.12/site-packages/jax_plugins/xla_cuda12/__init__.py", line 281, in _check_cuda_versions
    local_device_count = cuda_versions.cuda_device_count()
                         ^^^^^^^^^^^^^^^^^^^^^^^^^^^^^^^^^
RuntimeError: jaxlib/cuda/versions_helpers.cc:113: operation cuInit(0) failed: Unknown CUDA error 303; cuGetErrorName failed. This probably means that JAX was unable to load the CUDA libraries.
ERROR:2025-09-03 21:34:49,422:jax._src.xla_bridge:444: Jax plugin configuration error: Exception when calling jax_plugins.xla_cuda12.initialize()
Traceback (most recent call last):
  File "/home/fcastro/.conda/envs/desc-ray/lib/python3.12/site-packages/jax/_src/xla_bridge.py", line 442, in discover_pjrt_plugins
    plugin_module.initialize()
  File "/home/fcastro/.conda/envs/desc-ray/lib/python3.12/site-packages/jax_plugins/xla_cuda12/__init__.py", line 324, in initialize
    _check_cuda_versions(raise_on_first_error=True)
  File "/home/fcastro/.conda/envs/desc-ray/lib/python3.12/site-packages/jax_plugins/xla_cuda12/__init__.py", line 281, in _check_cuda_versions
    local_device_count = cuda_versions.cuda_device_count()
                         ^^^^^^^^^^^^^^^^^^^^^^^^^^^^^^^^^
RuntimeError: jaxlib/cuda/versions_helpers.cc:113: operation cuInit(0) failed: Unknown CUDA error 303; cuGetErrorName failed. This probably means that JAX was unable to load the CUDA libraries.
ERROR:2025-09-03 21:34:49,422:jax._src.xla_bridge:444: Jax plugin configuration error: Exception when calling jax_plugins.xla_cuda12.initialize()
Traceback (most recent call last):
  File "/home/fcastro/.conda/envs/desc-ray/lib/python3.12/site-packages/jax/_src/xla_bridge.py", line 442, in discover_pjrt_plugins
    plugin_module.initialize()
  File "/home/fcastro/.conda/envs/desc-ray/lib/python3.12/site-packages/jax_plugins/xla_cuda12/__init__.py", line 324, in initialize
    _check_cuda_versions(raise_on_first_error=True)
  File "/home/fcastro/.conda/envs/desc-ray/lib/python3.12/site-packages/jax_plugins/xla_cuda12/__init__.py", line 281, in _check_cuda_versions
    local_device_count = cuda_versions.cuda_device_count()
                         ^^^^^^^^^^^^^^^^^^^^^^^^^^^^^^^^^
RuntimeError: jaxlib/cuda/versions_helpers.cc:113: operation cuInit(0) failed: Unknown CUDA error 303; cuGetErrorName failed. This probably means that JAX was unable to load the CUDA libraries.
ERROR:2025-09-03 21:34:49,422:jax._src.xla_bridge:444: Jax plugin configuration error: Exception when calling jax_plugins.xla_cuda12.initialize()
Traceback (most recent call last):
  File "/home/fcastro/.conda/envs/desc-ray/lib/python3.12/site-packages/jax/_src/xla_bridge.py", line 442, in discover_pjrt_plugins
    plugin_module.initialize()
  File "/home/fcastro/.conda/envs/desc-ray/lib/python3.12/site-packages/jax_plugins/xla_cuda12/__init__.py", line 324, in initialize
    _check_cuda_versions(raise_on_first_error=True)
  File "/home/fcastro/.conda/envs/desc-ray/lib/python3.12/site-packages/jax_plugins/xla_cuda12/__init__.py", line 281, in _check_cuda_versions
    local_device_count = cuda_versions.cuda_device_count()
                         ^^^^^^^^^^^^^^^^^^^^^^^^^^^^^^^^^
RuntimeError: jaxlib/cuda/versions_helpers.cc:113: operation cuInit(0) failed: Unknown CUDA error 303; cuGetErrorName failed. This probably means that JAX was unable to load the CUDA libraries.
ERROR:2025-09-03 21:34:49,422:jax._src.xla_bridge:444: Jax plugin configuration error: Exception when calling jax_plugins.xla_cuda12.initialize()
Traceback (most recent call last):
  File "/home/fcastro/.conda/envs/desc-ray/lib/python3.12/site-packages/jax/_src/xla_bridge.py", line 442, in discover_pjrt_plugins
    plugin_module.initialize()
  File "/home/fcastro/.conda/envs/desc-ray/lib/python3.12/site-packages/jax_plugins/xla_cuda12/__init__.py", line 324, in initialize
    _check_cuda_versions(raise_on_first_error=True)
  File "/home/fcastro/.conda/envs/desc-ray/lib/python3.12/site-packages/jax_plugins/xla_cuda12/__init__.py", line 281, in _check_cuda_versions
    local_device_count = cuda_versions.cuda_device_count()
                         ^^^^^^^^^^^^^^^^^^^^^^^^^^^^^^^^^
RuntimeError: jaxlib/cuda/versions_helpers.cc:113: operation cuInit(0) failed: Unknown CUDA error 303; cuGetErrorName failed. This probably means that JAX was unable to load the CUDA libraries.
ERROR:2025-09-03 21:34:49,422:jax._src.xla_bridge:444: Jax plugin configuration error: Exception when calling jax_plugins.xla_cuda12.initialize()
Traceback (most recent call last):
  File "/home/fcastro/.conda/envs/desc-ray/lib/python3.12/site-packages/jax/_src/xla_bridge.py", line 442, in discover_pjrt_plugins
    plugin_module.initialize()
  File "/home/fcastro/.conda/envs/desc-ray/lib/python3.12/site-packages/jax_plugins/xla_cuda12/__init__.py", line 324, in initialize
    _check_cuda_versions(raise_on_first_error=True)
  File "/home/fcastro/.conda/envs/desc-ray/lib/python3.12/site-packages/jax_plugins/xla_cuda12/__init__.py", line 281, in _check_cuda_versions
    local_device_count = cuda_versions.cuda_device_count()
                         ^^^^^^^^^^^^^^^^^^^^^^^^^^^^^^^^^
RuntimeError: jaxlib/cuda/versions_helpers.cc:113: operation cuInit(0) failed: Unknown CUDA error 303; cuGetErrorName failed. This probably means that JAX was unable to load the CUDA libraries.
ERROR:2025-09-03 21:34:49,448:jax._src.xla_bridge:444: Jax plugin configuration error: Exception when calling jax_plugins.xla_cuda12.initialize()
Traceback (most recent call last):
  File "/home/fcastro/.conda/envs/desc-ray/lib/python3.12/site-packages/jax/_src/xla_bridge.py", line 442, in discover_pjrt_plugins
    plugin_module.initialize()
  File "/home/fcastro/.conda/envs/desc-ray/lib/python3.12/site-packages/jax_plugins/xla_cuda12/__init__.py", line 324, in initialize
    _check_cuda_versions(raise_on_first_error=True)
  File "/home/fcastro/.conda/envs/desc-ray/lib/python3.12/site-packages/jax_plugins/xla_cuda12/__init__.py", line 281, in _check_cuda_versions
    local_device_count = cuda_versions.cuda_device_count()
                         ^^^^^^^^^^^^^^^^^^^^^^^^^^^^^^^^^
RuntimeError: jaxlib/cuda/versions_helpers.cc:113: operation cuInit(0) failed: Unknown CUDA error 303; cuGetErrorName failed. This probably means that JAX was unable to load the CUDA libraries.
ERROR:2025-09-03 21:34:49,448:jax._src.xla_bridge:444: Jax plugin configuration error: Exception when calling jax_plugins.xla_cuda12.initialize()
Traceback (most recent call last):
  File "/home/fcastro/.conda/envs/desc-ray/lib/python3.12/site-packages/jax/_src/xla_bridge.py", line 442, in discover_pjrt_plugins
    plugin_module.initialize()
  File "/home/fcastro/.conda/envs/desc-ray/lib/python3.12/site-packages/jax_plugins/xla_cuda12/__init__.py", line 324, in initialize
    _check_cuda_versions(raise_on_first_error=True)
  File "/home/fcastro/.conda/envs/desc-ray/lib/python3.12/site-packages/jax_plugins/xla_cuda12/__init__.py", line 281, in _check_cuda_versions
    local_device_count = cuda_versions.cuda_device_count()
                         ^^^^^^^^^^^^^^^^^^^^^^^^^^^^^^^^^
RuntimeError: jaxlib/cuda/versions_helpers.cc:113: operation cuInit(0) failed: Unknown CUDA error 303; cuGetErrorName failed. This probably means that JAX was unable to load the CUDA libraries.
ERROR:2025-09-03 21:34:49,448:jax._src.xla_bridge:444: Jax plugin configuration error: Exception when calling jax_plugins.xla_cuda12.initialize()
Traceback (most recent call last):
  File "/home/fcastro/.conda/envs/desc-ray/lib/python3.12/site-packages/jax/_src/xla_bridge.py", line 442, in discover_pjrt_plugins
    plugin_module.initialize()
  File "/home/fcastro/.conda/envs/desc-ray/lib/python3.12/site-packages/jax_plugins/xla_cuda12/__init__.py", line 324, in initialize
    _check_cuda_versions(raise_on_first_error=True)
  File "/home/fcastro/.conda/envs/desc-ray/lib/python3.12/site-packages/jax_plugins/xla_cuda12/__init__.py", line 281, in _check_cuda_versions
    local_device_count = cuda_versions.cuda_device_count()
                         ^^^^^^^^^^^^^^^^^^^^^^^^^^^^^^^^^
RuntimeError: jaxlib/cuda/versions_helpers.cc:113: operation cuInit(0) failed: Unknown CUDA error 303; cuGetErrorName failed. This probably means that JAX was unable to load the CUDA libraries.
ERROR:2025-09-03 21:34:49,448:jax._src.xla_bridge:444: Jax plugin configuration error: Exception when calling jax_plugins.xla_cuda12.initialize()
Traceback (most recent call last):
  File "/home/fcastro/.conda/envs/desc-ray/lib/python3.12/site-packages/jax/_src/xla_bridge.py", line 442, in discover_pjrt_plugins
    plugin_module.initialize()
  File "/home/fcastro/.conda/envs/desc-ray/lib/python3.12/site-packages/jax_plugins/xla_cuda12/__init__.py", line 324, in initialize
    _check_cuda_versions(raise_on_first_error=True)
  File "/home/fcastro/.conda/envs/desc-ray/lib/python3.12/site-packages/jax_plugins/xla_cuda12/__init__.py", line 281, in _check_cuda_versions
    local_device_count = cuda_versions.cuda_device_count()
                         ^^^^^^^^^^^^^^^^^^^^^^^^^^^^^^^^^
RuntimeError: jaxlib/cuda/versions_helpers.cc:113: operation cuInit(0) failed: Unknown CUDA error 303; cuGetErrorName failed. This probably means that JAX was unable to load the CUDA libraries.
ERROR:2025-09-03 21:34:49,448:jax._src.xla_bridge:444: Jax plugin configuration error: Exception when calling jax_plugins.xla_cuda12.initialize()
Traceback (most recent call last):
  File "/home/fcastro/.conda/envs/desc-ray/lib/python3.12/site-packages/jax/_src/xla_bridge.py", line 442, in discover_pjrt_plugins
    plugin_module.initialize()
  File "/home/fcastro/.conda/envs/desc-ray/lib/python3.12/site-packages/jax_plugins/xla_cuda12/__init__.py", line 324, in initialize
    _check_cuda_versions(raise_on_first_error=True)
  File "/home/fcastro/.conda/envs/desc-ray/lib/python3.12/site-packages/jax_plugins/xla_cuda12/__init__.py", line 281, in _check_cuda_versions
    local_device_count = cuda_versions.cuda_device_count()
                         ^^^^^^^^^^^^^^^^^^^^^^^^^^^^^^^^^
RuntimeError: jaxlib/cuda/versions_helpers.cc:113: operation cuInit(0) failed: Unknown CUDA error 303; cuGetErrorName failed. This probably means that JAX was unable to load the CUDA libraries.
ERROR:2025-09-03 21:34:49,448:jax._src.xla_bridge:444: Jax plugin configuration error: Exception when calling jax_plugins.xla_cuda12.initialize()
Traceback (most recent call last):
  File "/home/fcastro/.conda/envs/desc-ray/lib/python3.12/site-packages/jax/_src/xla_bridge.py", line 442, in discover_pjrt_plugins
    plugin_module.initialize()
  File "/home/fcastro/.conda/envs/desc-ray/lib/python3.12/site-packages/jax_plugins/xla_cuda12/__init__.py", line 324, in initialize
    _check_cuda_versions(raise_on_first_error=True)
  File "/home/fcastro/.conda/envs/desc-ray/lib/python3.12/site-packages/jax_plugins/xla_cuda12/__init__.py", line 281, in _check_cuda_versions
    local_device_count = cuda_versions.cuda_device_count()
                         ^^^^^^^^^^^^^^^^^^^^^^^^^^^^^^^^^
RuntimeError: jaxlib/cuda/versions_helpers.cc:113: operation cuInit(0) failed: Unknown CUDA error 303; cuGetErrorName failed. This probably means that JAX was unable to load the CUDA libraries.
ERROR:2025-09-03 21:34:49,448:jax._src.xla_bridge:444: Jax plugin configuration error: Exception when calling jax_plugins.xla_cuda12.initialize()
Traceback (most recent call last):
  File "/home/fcastro/.conda/envs/desc-ray/lib/python3.12/site-packages/jax/_src/xla_bridge.py", line 442, in discover_pjrt_plugins
    plugin_module.initialize()
  File "/home/fcastro/.conda/envs/desc-ray/lib/python3.12/site-packages/jax_plugins/xla_cuda12/__init__.py", line 324, in initialize
    _check_cuda_versions(raise_on_first_error=True)
  File "/home/fcastro/.conda/envs/desc-ray/lib/python3.12/site-packages/jax_plugins/xla_cuda12/__init__.py", line 281, in _check_cuda_versions
    local_device_count = cuda_versions.cuda_device_count()
                         ^^^^^^^^^^^^^^^^^^^^^^^^^^^^^^^^^
RuntimeError: jaxlib/cuda/versions_helpers.cc:113: operation cuInit(0) failed: Unknown CUDA error 303; cuGetErrorName failed. This probably means that JAX was unable to load the CUDA libraries.
ERROR:2025-09-03 21:34:49,448:jax._src.xla_bridge:444: Jax plugin configuration error: Exception when calling jax_plugins.xla_cuda12.initialize()
Traceback (most recent call last):
  File "/home/fcastro/.conda/envs/desc-ray/lib/python3.12/site-packages/jax/_src/xla_bridge.py", line 442, in discover_pjrt_plugins
    plugin_module.initialize()
  File "/home/fcastro/.conda/envs/desc-ray/lib/python3.12/site-packages/jax_plugins/xla_cuda12/__init__.py", line 324, in initialize
    _check_cuda_versions(raise_on_first_error=True)
  File "/home/fcastro/.conda/envs/desc-ray/lib/python3.12/site-packages/jax_plugins/xla_cuda12/__init__.py", line 281, in _check_cuda_versions
    local_device_count = cuda_versions.cuda_device_count()
                         ^^^^^^^^^^^^^^^^^^^^^^^^^^^^^^^^^
RuntimeError: jaxlib/cuda/versions_helpers.cc:113: operation cuInit(0) failed: Unknown CUDA error 303; cuGetErrorName failed. This probably means that JAX was unable to load the CUDA libraries.
ERROR:2025-09-03 21:34:49,449:jax._src.xla_bridge:444: Jax plugin configuration error: Exception when calling jax_plugins.xla_cuda12.initialize()
Traceback (most recent call last):
  File "/home/fcastro/.conda/envs/desc-ray/lib/python3.12/site-packages/jax/_src/xla_bridge.py", line 442, in discover_pjrt_plugins
    plugin_module.initialize()
  File "/home/fcastro/.conda/envs/desc-ray/lib/python3.12/site-packages/jax_plugins/xla_cuda12/__init__.py", line 324, in initialize
    _check_cuda_versions(raise_on_first_error=True)
  File "/home/fcastro/.conda/envs/desc-ray/lib/python3.12/site-packages/jax_plugins/xla_cuda12/__init__.py", line 281, in _check_cuda_versions
    local_device_count = cuda_versions.cuda_device_count()
                         ^^^^^^^^^^^^^^^^^^^^^^^^^^^^^^^^^
RuntimeError: jaxlib/cuda/versions_helpers.cc:113: operation cuInit(0) failed: Unknown CUDA error 303; cuGetErrorName failed. This probably means that JAX was unable to load the CUDA libraries.
ERROR:2025-09-03 21:34:49,461:jax._src.xla_bridge:444: Jax plugin configuration error: Exception when calling jax_plugins.xla_cuda12.initialize()
Traceback (most recent call last):
  File "/home/fcastro/.conda/envs/desc-ray/lib/python3.12/site-packages/jax/_src/xla_bridge.py", line 442, in discover_pjrt_plugins
    plugin_module.initialize()
  File "/home/fcastro/.conda/envs/desc-ray/lib/python3.12/site-packages/jax_plugins/xla_cuda12/__init__.py", line 324, in initialize
    _check_cuda_versions(raise_on_first_error=True)
  File "/home/fcastro/.conda/envs/desc-ray/lib/python3.12/site-packages/jax_plugins/xla_cuda12/__init__.py", line 281, in _check_cuda_versions
    local_device_count = cuda_versions.cuda_device_count()
                         ^^^^^^^^^^^^^^^^^^^^^^^^^^^^^^^^^
RuntimeError: jaxlib/cuda/versions_helpers.cc:113: operation cuInit(0) failed: Unknown CUDA error 303; cuGetErrorName failed. This probably means that JAX was unable to load the CUDA libraries.
ERROR:2025-09-03 21:34:49,461:jax._src.xla_bridge:444: Jax plugin configuration error: Exception when calling jax_plugins.xla_cuda12.initialize()
Traceback (most recent call last):
  File "/home/fcastro/.conda/envs/desc-ray/lib/python3.12/site-packages/jax/_src/xla_bridge.py", line 442, in discover_pjrt_plugins
    plugin_module.initialize()
  File "/home/fcastro/.conda/envs/desc-ray/lib/python3.12/site-packages/jax_plugins/xla_cuda12/__init__.py", line 324, in initialize
    _check_cuda_versions(raise_on_first_error=True)
  File "/home/fcastro/.conda/envs/desc-ray/lib/python3.12/site-packages/jax_plugins/xla_cuda12/__init__.py", line 281, in _check_cuda_versions
    local_device_count = cuda_versions.cuda_device_count()
                         ^^^^^^^^^^^^^^^^^^^^^^^^^^^^^^^^^
RuntimeError: jaxlib/cuda/versions_helpers.cc:113: operation cuInit(0) failed: Unknown CUDA error 303; cuGetErrorName failed. This probably means that JAX was unable to load the CUDA libraries.
ERROR:2025-09-03 21:34:49,461:jax._src.xla_bridge:444: Jax plugin configuration error: Exception when calling jax_plugins.xla_cuda12.initialize()
Traceback (most recent call last):
  File "/home/fcastro/.conda/envs/desc-ray/lib/python3.12/site-packages/jax/_src/xla_bridge.py", line 442, in discover_pjrt_plugins
    plugin_module.initialize()
  File "/home/fcastro/.conda/envs/desc-ray/lib/python3.12/site-packages/jax_plugins/xla_cuda12/__init__.py", line 324, in initialize
    _check_cuda_versions(raise_on_first_error=True)
  File "/home/fcastro/.conda/envs/desc-ray/lib/python3.12/site-packages/jax_plugins/xla_cuda12/__init__.py", line 281, in _check_cuda_versions
    local_device_count = cuda_versions.cuda_device_count()
                         ^^^^^^^^^^^^^^^^^^^^^^^^^^^^^^^^^
RuntimeError: jaxlib/cuda/versions_helpers.cc:113: operation cuInit(0) failed: Unknown CUDA error 303; cuGetErrorName failed. This probably means that JAX was unable to load the CUDA libraries.
ERROR:2025-09-03 21:34:49,461:jax._src.xla_bridge:444: Jax plugin configuration error: Exception when calling jax_plugins.xla_cuda12.initialize()
Traceback (most recent call last):
  File "/home/fcastro/.conda/envs/desc-ray/lib/python3.12/site-packages/jax/_src/xla_bridge.py", line 442, in discover_pjrt_plugins
    plugin_module.initialize()
  File "/home/fcastro/.conda/envs/desc-ray/lib/python3.12/site-packages/jax_plugins/xla_cuda12/__init__.py", line 324, in initialize
    _check_cuda_versions(raise_on_first_error=True)
  File "/home/fcastro/.conda/envs/desc-ray/lib/python3.12/site-packages/jax_plugins/xla_cuda12/__init__.py", line 281, in _check_cuda_versions
    local_device_count = cuda_versions.cuda_device_count()
                         ^^^^^^^^^^^^^^^^^^^^^^^^^^^^^^^^^
RuntimeError: jaxlib/cuda/versions_helpers.cc:113: operation cuInit(0) failed: Unknown CUDA error 303; cuGetErrorName failed. This probably means that JAX was unable to load the CUDA libraries.
ERROR:2025-09-03 21:34:49,461:jax._src.xla_bridge:444: Jax plugin configuration error: Exception when calling jax_plugins.xla_cuda12.initialize()
Traceback (most recent call last):
  File "/home/fcastro/.conda/envs/desc-ray/lib/python3.12/site-packages/jax/_src/xla_bridge.py", line 442, in discover_pjrt_plugins
    plugin_module.initialize()
  File "/home/fcastro/.conda/envs/desc-ray/lib/python3.12/site-packages/jax_plugins/xla_cuda12/__init__.py", line 324, in initialize
    _check_cuda_versions(raise_on_first_error=True)
  File "/home/fcastro/.conda/envs/desc-ray/lib/python3.12/site-packages/jax_plugins/xla_cuda12/__init__.py", line 281, in _check_cuda_versions
    local_device_count = cuda_versions.cuda_device_count()
                         ^^^^^^^^^^^^^^^^^^^^^^^^^^^^^^^^^
RuntimeError: jaxlib/cuda/versions_helpers.cc:113: operation cuInit(0) failed: Unknown CUDA error 303; cuGetErrorName failed. This probably means that JAX was unable to load the CUDA libraries.
ERROR:2025-09-03 21:34:49,461:jax._src.xla_bridge:444: Jax plugin configuration error: Exception when calling jax_plugins.xla_cuda12.initialize()
Traceback (most recent call last):
  File "/home/fcastro/.conda/envs/desc-ray/lib/python3.12/site-packages/jax/_src/xla_bridge.py", line 442, in discover_pjrt_plugins
    plugin_module.initialize()
  File "/home/fcastro/.conda/envs/desc-ray/lib/python3.12/site-packages/jax_plugins/xla_cuda12/__init__.py", line 324, in initialize
    _check_cuda_versions(raise_on_first_error=True)
  File "/home/fcastro/.conda/envs/desc-ray/lib/python3.12/site-packages/jax_plugins/xla_cuda12/__init__.py", line 281, in _check_cuda_versions
    local_device_count = cuda_versions.cuda_device_count()
                         ^^^^^^^^^^^^^^^^^^^^^^^^^^^^^^^^^
RuntimeError: jaxlib/cuda/versions_helpers.cc:113: operation cuInit(0) failed: Unknown CUDA error 303; cuGetErrorName failed. This probably means that JAX was unable to load the CUDA libraries.
ERROR:2025-09-03 21:34:49,461:jax._src.xla_bridge:444: Jax plugin configuration error: Exception when calling jax_plugins.xla_cuda12.initialize()
Traceback (most recent call last):
  File "/home/fcastro/.conda/envs/desc-ray/lib/python3.12/site-packages/jax/_src/xla_bridge.py", line 442, in discover_pjrt_plugins
    plugin_module.initialize()
  File "/home/fcastro/.conda/envs/desc-ray/lib/python3.12/site-packages/jax_plugins/xla_cuda12/__init__.py", line 324, in initialize
    _check_cuda_versions(raise_on_first_error=True)
  File "/home/fcastro/.conda/envs/desc-ray/lib/python3.12/site-packages/jax_plugins/xla_cuda12/__init__.py", line 281, in _check_cuda_versions
    local_device_count = cuda_versions.cuda_device_count()
                         ^^^^^^^^^^^^^^^^^^^^^^^^^^^^^^^^^
RuntimeError: jaxlib/cuda/versions_helpers.cc:113: operation cuInit(0) failed: Unknown CUDA error 303; cuGetErrorName failed. This probably means that JAX was unable to load the CUDA libraries.
ERROR:2025-09-03 21:34:49,461:jax._src.xla_bridge:444: Jax plugin configuration error: Exception when calling jax_plugins.xla_cuda12.initialize()
Traceback (most recent call last):
  File "/home/fcastro/.conda/envs/desc-ray/lib/python3.12/site-packages/jax/_src/xla_bridge.py", line 442, in discover_pjrt_plugins
    plugin_module.initialize()
  File "/home/fcastro/.conda/envs/desc-ray/lib/python3.12/site-packages/jax_plugins/xla_cuda12/__init__.py", line 324, in initialize
    _check_cuda_versions(raise_on_first_error=True)
  File "/home/fcastro/.conda/envs/desc-ray/lib/python3.12/site-packages/jax_plugins/xla_cuda12/__init__.py", line 281, in _check_cuda_versions
    local_device_count = cuda_versions.cuda_device_count()
                         ^^^^^^^^^^^^^^^^^^^^^^^^^^^^^^^^^
RuntimeError: jaxlib/cuda/versions_helpers.cc:113: operation cuInit(0) failed: Unknown CUDA error 303; cuGetErrorName failed. This probably means that JAX was unable to load the CUDA libraries.
ERROR:2025-09-03 21:34:49,461:jax._src.xla_bridge:444: Jax plugin configuration error: Exception when calling jax_plugins.xla_cuda12.initialize()
Traceback (most recent call last):
  File "/home/fcastro/.conda/envs/desc-ray/lib/python3.12/site-packages/jax/_src/xla_bridge.py", line 442, in discover_pjrt_plugins
    plugin_module.initialize()
  File "/home/fcastro/.conda/envs/desc-ray/lib/python3.12/site-packages/jax_plugins/xla_cuda12/__init__.py", line 324, in initialize
    _check_cuda_versions(raise_on_first_error=True)
  File "/home/fcastro/.conda/envs/desc-ray/lib/python3.12/site-packages/jax_plugins/xla_cuda12/__init__.py", line 281, in _check_cuda_versions
    local_device_count = cuda_versions.cuda_device_count()
                         ^^^^^^^^^^^^^^^^^^^^^^^^^^^^^^^^^
RuntimeError: jaxlib/cuda/versions_helpers.cc:113: operation cuInit(0) failed: Unknown CUDA error 303; cuGetErrorName failed. This probably means that JAX was unable to load the CUDA libraries.
<frozen importlib._bootstrap>:488: RuntimeWarning: suspicious MPI execution environment
Your environment has OMPI_COMM_WORLD_SIZE=36 set, but mpi4py was built with MPICH.
You may be using `mpiexec` or `mpirun` from a different MPI implementation.
<frozen importlib._bootstrap>:488: RuntimeWarning: suspicious MPI execution environment
Your environment has OMPI_COMM_WORLD_SIZE=36 set, but mpi4py was built with MPICH.
You may be using `mpiexec` or `mpirun` from a different MPI implementation.
<frozen importlib._bootstrap>:488: RuntimeWarning: suspicious MPI execution environment
Your environment has OMPI_COMM_WORLD_SIZE=36 set, but mpi4py was built with MPICH.
You may be using `mpiexec` or `mpirun` from a different MPI implementation.
<frozen importlib._bootstrap>:488: RuntimeWarning: suspicious MPI execution environment
Your environment has OMPI_COMM_WORLD_SIZE=36 set, but mpi4py was built with MPICH.
You may be using `mpiexec` or `mpirun` from a different MPI implementation.
<frozen importlib._bootstrap>:488: RuntimeWarning: suspicious MPI execution environment
Your environment has OMPI_COMM_WORLD_SIZE=36 set, but mpi4py was built with MPICH.
You may be using `mpiexec` or `mpirun` from a different MPI implementation.
<frozen importlib._bootstrap>:488: RuntimeWarning: suspicious MPI execution environment
Your environment has OMPI_COMM_WORLD_SIZE=36 set, but mpi4py was built with MPICH.
You may be using `mpiexec` or `mpirun` from a different MPI implementation.
<frozen importlib._bootstrap>:488: RuntimeWarning: suspicious MPI execution environment
Your environment has OMPI_COMM_WORLD_SIZE=36 set, but mpi4py was built with MPICH.
You may be using `mpiexec` or `mpirun` from a different MPI implementation.
<frozen importlib._bootstrap>:488: RuntimeWarning: suspicious MPI execution environment
Your environment has OMPI_COMM_WORLD_SIZE=36 set, but mpi4py was built with MPICH.
You may be using `mpiexec` or `mpirun` from a different MPI implementation.
<frozen importlib._bootstrap>:488: RuntimeWarning: suspicious MPI execution environment
Your environment has OMPI_COMM_WORLD_SIZE=36 set, but mpi4py was built with MPICH.
You may be using `mpiexec` or `mpirun` from a different MPI implementation.
<frozen importlib._bootstrap>:488: RuntimeWarning: suspicious MPI execution environment
Your environment has OMPI_COMM_WORLD_SIZE=36 set, but mpi4py was built with MPICH.
You may be using `mpiexec` or `mpirun` from a different MPI implementation.
<frozen importlib._bootstrap>:488: RuntimeWarning: suspicious MPI execution environment
Your environment has OMPI_COMM_WORLD_SIZE=36 set, but mpi4py was built with MPICH.
You may be using `mpiexec` or `mpirun` from a different MPI implementation.
<frozen importlib._bootstrap>:488: RuntimeWarning: suspicious MPI execution environment
Your environment has OMPI_COMM_WORLD_SIZE=36 set, but mpi4py was built with MPICH.
You may be using `mpiexec` or `mpirun` from a different MPI implementation.
<frozen importlib._bootstrap>:488: RuntimeWarning: suspicious MPI execution environment
Your environment has OMPI_COMM_WORLD_SIZE=36 set, but mpi4py was built with MPICH.
You may be using `mpiexec` or `mpirun` from a different MPI implementation.
<frozen importlib._bootstrap>:488: RuntimeWarning: suspicious MPI execution environment
Your environment has OMPI_COMM_WORLD_SIZE=36 set, but mpi4py was built with MPICH.
You may be using `mpiexec` or `mpirun` from a different MPI implementation.
<frozen importlib._bootstrap>:488: RuntimeWarning: suspicious MPI execution environment
Your environment has OMPI_COMM_WORLD_SIZE=36 set, but mpi4py was built with MPICH.
You may be using `mpiexec` or `mpirun` from a different MPI implementation.
<frozen importlib._bootstrap>:488: RuntimeWarning: suspicious MPI execution environment
Your environment has OMPI_COMM_WORLD_SIZE=36 set, but mpi4py was built with MPICH.
You may be using `mpiexec` or `mpirun` from a different MPI implementation.
<frozen importlib._bootstrap>:488: RuntimeWarning: suspicious MPI execution environment
Your environment has OMPI_COMM_WORLD_SIZE=36 set, but mpi4py was built with MPICH.
You may be using `mpiexec` or `mpirun` from a different MPI implementation.
<frozen importlib._bootstrap>:488: RuntimeWarning: suspicious MPI execution environment
Your environment has OMPI_COMM_WORLD_SIZE=36 set, but mpi4py was built with MPICH.
You may be using `mpiexec` or `mpirun` from a different MPI implementation.
<frozen importlib._bootstrap>:488: RuntimeWarning: suspicious MPI execution environment
Your environment has OMPI_COMM_WORLD_SIZE=36 set, but mpi4py was built with MPICH.
You may be using `mpiexec` or `mpirun` from a different MPI implementation.
<frozen importlib._bootstrap>:488: RuntimeWarning: suspicious MPI execution environment
Your environment has OMPI_COMM_WORLD_SIZE=36 set, but mpi4py was built with MPICH.
You may be using `mpiexec` or `mpirun` from a different MPI implementation.
<frozen importlib._bootstrap>:488: RuntimeWarning: suspicious MPI execution environment
Your environment has OMPI_COMM_WORLD_SIZE=36 set, but mpi4py was built with MPICH.
You may be using `mpiexec` or `mpirun` from a different MPI implementation.
<frozen importlib._bootstrap>:488: RuntimeWarning: suspicious MPI execution environment
Your environment has OMPI_COMM_WORLD_SIZE=36 set, but mpi4py was built with MPICH.
You may be using `mpiexec` or `mpirun` from a different MPI implementation.
<frozen importlib._bootstrap>:488: RuntimeWarning: suspicious MPI execution environment
Your environment has OMPI_COMM_WORLD_SIZE=36 set, but mpi4py was built with MPICH.
You may be using `mpiexec` or `mpirun` from a different MPI implementation.
<frozen importlib._bootstrap>:488: RuntimeWarning: suspicious MPI execution environment
Your environment has OMPI_COMM_WORLD_SIZE=36 set, but mpi4py was built with MPICH.
You may be using `mpiexec` or `mpirun` from a different MPI implementation.
<frozen importlib._bootstrap>:488: RuntimeWarning: suspicious MPI execution environment
Your environment has OMPI_COMM_WORLD_SIZE=36 set, but mpi4py was built with MPICH.
You may be using `mpiexec` or `mpirun` from a different MPI implementation.
<frozen importlib._bootstrap>:488: RuntimeWarning: suspicious MPI execution environment
Your environment has OMPI_COMM_WORLD_SIZE=36 set, but mpi4py was built with MPICH.
You may be using `mpiexec` or `mpirun` from a different MPI implementation.
<frozen importlib._bootstrap>:488: RuntimeWarning: suspicious MPI execution environment
Your environment has OMPI_COMM_WORLD_SIZE=36 set, but mpi4py was built with MPICH.
You may be using `mpiexec` or `mpirun` from a different MPI implementation.
<frozen importlib._bootstrap>:488: RuntimeWarning: suspicious MPI execution environment
Your environment has OMPI_COMM_WORLD_SIZE=36 set, but mpi4py was built with MPICH.
You may be using `mpiexec` or `mpirun` from a different MPI implementation.
<frozen importlib._bootstrap>:488: RuntimeWarning: suspicious MPI execution environment
Your environment has OMPI_COMM_WORLD_SIZE=36 set, but mpi4py was built with MPICH.
You may be using `mpiexec` or `mpirun` from a different MPI implementation.
<frozen importlib._bootstrap>:488: RuntimeWarning: suspicious MPI execution environment
Your environment has OMPI_COMM_WORLD_SIZE=36 set, but mpi4py was built with MPICH.
You may be using `mpiexec` or `mpirun` from a different MPI implementation.
<frozen importlib._bootstrap>:488: RuntimeWarning: suspicious MPI execution environment
Your environment has OMPI_COMM_WORLD_SIZE=36 set, but mpi4py was built with MPICH.
You may be using `mpiexec` or `mpirun` from a different MPI implementation.
<frozen importlib._bootstrap>:488: RuntimeWarning: suspicious MPI execution environment
Your environment has OMPI_COMM_WORLD_SIZE=36 set, but mpi4py was built with MPICH.
You may be using `mpiexec` or `mpirun` from a different MPI implementation.
<frozen importlib._bootstrap>:488: RuntimeWarning: suspicious MPI execution environment
Your environment has OMPI_COMM_WORLD_SIZE=36 set, but mpi4py was built with MPICH.
You may be using `mpiexec` or `mpirun` from a different MPI implementation.
<frozen importlib._bootstrap>:488: RuntimeWarning: suspicious MPI execution environment
Your environment has OMPI_COMM_WORLD_SIZE=36 set, but mpi4py was built with MPICH.
You may be using `mpiexec` or `mpirun` from a different MPI implementation.
<frozen importlib._bootstrap>:488: RuntimeWarning: suspicious MPI execution environment
Your environment has OMPI_COMM_WORLD_SIZE=36 set, but mpi4py was built with MPICH.
You may be using `mpiexec` or `mpirun` from a different MPI implementation.
<frozen importlib._bootstrap>:488: RuntimeWarning: suspicious MPI execution environment
Your environment has OMPI_COMM_WORLD_SIZE=36 set, but mpi4py was built with MPICH.
You may be using `mpiexec` or `mpirun` from a different MPI implementation.
--------------------------------------------------------------------------
Primary job  terminated normally, but 1 process returned
a non-zero exit code. Per user-direction, the job has been aborted.
--------------------------------------------------------------------------
--------------------------------------------------------------------------
mpiexec noticed that process rank 29 with PID 2185577 on node stellar-i05n14 exited on signal 9 (Killed).
--------------------------------------------------------------------------
slurmstepd: error: Detected 3 oom_kill events in StepId=2172795.batch. Some of the step tasks have been OOM Killed.
